Workbook

Sheet Premissas
A1: RealRisk — Premissas do Modelo (Cenário Esperado)
A2: Moeda: USD · Ano 1 = Jul/2026–Jun/2027 · Células azuis = inputs editáveis
A4: VOLUMES E PREÇOS | B4: Ano 1 | C4: Ano 2 | D4: Ano 3 | E4: Fonte / racional
A5: Assinantes médios ativos no ano | B5: 40 | C5: 150 | D5: 290 | E5: Ramp: 100 fim A1, 200 fim A2, ~380 fim A3 (playbook ajustado por churn 25–35%)
A6: Preço assinatura (US$/ano) | B6: 1200 | C6: 1200 | D6: 1200 | E6: Modelo de negócio Notion
A7: Kit Desembarque — unidades | B7: 100 | C7: 250 | D7: 400 | E7: Cursos v2, degrau 1
A8: Kit Desembarque — preço | B8: 120 | C8: 120 | D8: 120 | E8: Cursos v2: $97–147 (média)
A9: Trilha 1 — unidades | B9: 30 | C9: 80 | D9: 110 | E9: Lança no gate de 100 assinantes (Fase 6)
A10: Trilha 1 — preço | B10: 497 | C10: 497 | D10: 497 | E10: Cursos v2
A11: Trilha 2 — unidades | B11: 8 | C11: 35 | D11: 60 | E11: Lança por último (depende de Deal Rooms)
A12: Trilha 2 — preço | B12: 997 | C12: 997 | D12: 997 | E12: Cursos v2 (reprecificada)
A13: Trilha 3 — unidades | B13: 12 | C13: 40 | D13: 65 | E13: Depende de gravações com parceiros
A14: Trilha 3 — preço | B14: 397 | C14: 397 | D14: 397 | E14: Cursos v2 (reprecificada)
A15: Análise de Deal Avulsa — unidades | B15: 15 | C15: 45 | D15: 85 | E15: Cursos v2, degrau 5
A16: Análise de Deal Avulsa — preço | B16: 397 | C16: 397 | D16: 397 | E16: Cursos v2: $297–497 (média)
... A27: Radar trimestral avulso + patrocínio B2B | B27: 1000 | C27: 6000 | D27: 18000 | E27: Cursos v2 §4 — patrocínio só após Fase 5
A28: CUSTOS DIRETOS (CSP)
A29: Taxas de pagamento/plataforma (% receita assin.+cursos) | B29: 0.06 | C29: 0.06 | D29: 0.06 | E29: Stripe/Hotmart/Circle ~4–8%
A30: Comissão de afiliados (% receita assin.+cursos) | B30: 0.04 | C30: 0.05 | D30: 0.05 | E30: 10% sobre ~40–50% das vendas atribuídas
A31: Repasse a parceiros — serviços/mentoria/flips (%) | B31: 0.4 | C31: 0.4 | D31: 0.4 | E31: Split Jales sobre serviços de deal, mentoria e flips
A32: Custo direto por inspeção (US$) | B32: 500 | C32: 500 | D32: 500 | E32: Inspetor terceirizado/ferramentas
A33: Custo direto por due diligence (US$) | B33: 800 | C33: 800 | D33: 800 | E33: Buscas, relatórios, terceiros
A34: Infra plataforma (Circle+SimplyRETS+APIs+hosting)/ano | B34: 4400 | C34: 5800 | D34: 7500 | E34: Circle ~$2,6k + SimplyRETS $600 + APIs/VPS
A35: Produção e edição de conteúdo/cursos (ano) | B35: 6000 | C35: 10000 | D35: 14000 | E35: Edição vídeos, plataforma de curso
A36: DESPESAS OPERACIONAIS
A37: Marketing e ferramentas de distribuição | B37: 4000 | C37: 12000 | D37: 22000 | E37: Orgânico + afiliados já no CSP; aqui só ferramentas/eventos
A38: Pró-labore Edifico (gestão da tecnologia) | B38: 12000 | C38: 24000 | D38: 36000 | E38: Custo econômico da hora do operador
A39: Contabilidade, jurídico e compliance (BR+US) | B39: 3000 | C39: 7000 | D39: 9000 | E39: Inclui parecer securities US no A2 (pré-Fase 7)
A40: Software e administrativas | B40: 2000 | C40: 3000 | D40: 4000
A41: Analista/VA (gatilho Fase 7) | B41: 0 | C41: 8000 | D41: 18000 | E41: Contratação playbook Fase 7
A42: IMPOSTOS, CAPEX E CAPITAL
A43: Impostos sobre receita (deduções) % | B43: 0.1 | C43: 0.1 | D43: 0.1 | E43: ⚠️ Assunção simplificada — definir estrutura societária BR/US
A44: IR/CSLL sobre LAIR % | B44: 0.15 | C44: 0.15 | D44: 0.15 | E44: ⚠️ Assunção simplificada — validar com contador
A45: Capex (equipamentos/gravação) | B45: 3000 | C45: 1500 | D45: 1500 | E45: Depreciação linear 3 anos
A46: Capital próprio aportado (acumulado) | B46: 12000 | C46: 12000 | D46: 12000 | E46: Aporte inicial Lucas/sócios
A47: Receita diferida (% da receita anual de assinaturas) | B47: 0.35 | C47: 0.35 | D47: 0.35 | E47: Assinaturas anuais pagas antecipadas ainda não apropriadas
A48: Contas a receber (% receita bruta) | B48: 0.05 | C48: 0.05 | D48: 0.05 | E48: Recebíveis de cursos parcelados/serviços
A49: Contas a pagar (% custos+despesas) | B49: 0.04 | C49: 0.04 | D49: 0.04 | E49: Fornecedores/repasse a pagar

Sheet DRE
A1: RealRisk — DRE Projetada (3 anos, US$)
B3: Ano 1 | C3: AV % | D3: Ano 2 | E3: AV % | F3: AH % | G3: Ano 3 | H3: AV % | I3: AH %
A4: RECEITA BRUTA
A5: Assinaturas Circle | B5: =Premissas!B5*Premissas!B6 -> 48000 | C5: =IF(B19=0,0,B5/B19) -> 0.38039537 | D5: =Premissas!C5*Premissas!C6 -> 180000 | E5: =IF(D19=0,0,D5/D19) -> 0.4415011 | F5: =IF(B5=0,0,(D5-B5)/ABS(B5)) -> 2.75 | G5: =Premissas!D5*Premissas!D6 -> 348000 | H5: =IF(G19=0,0,G5/G19) -> 0.47186697 | I5: =IF(D5=0,0,(G5-D5)/ABS(D5)) -> 0.93333333
A6: Kit Desembarque | B6: =Premissas!B7*Premissas!B8 -> 12000 | C6: =IF(B19=0,0,B6/B19) -> 0.095098843 | D6: =Premissas!C7*Premissas!C8 -> 30000 | E6: =IF(D19=0,0,D6/D19) -> 0.073583517 | F6: =IF(B6=0,0,(D6-B6)/ABS(B6)) -> 1.5 | G6: =Premissas!D7*Premissas!D8 -> 48000 | H6: =IF(G19=0,0,G6/G19) -> 0.065085099 | I6: =IF(D6=0,0,(G6-D6)/ABS(D6)) -> 0.6
A7: Trilha 1 — Fundamentos | B7: =Premissas!B9*Premissas!B10 -> 14910 | C7: =IF(B19=0,0,B7/B19) -> 0.11816031 | D7: =Premissas!C9*Premissas!C10 -> 39760 | E7: =IF(D19=0,0,D7/D19) -> 0.097522688 | F7: =IF(B7=0,0,(D7-B7)/ABS(B7)) -> 1.6666667 | G7: =Premissas!D9*Premissas!D10 -> 54670 | H7: =IF(G19=0,0,G7/G19) -> 0.074129216 | I7: =IF(D7=0,0,(G7-D7)/ABS(D7)) -> 0.375
A8: Trilha 2 — Avançado | B8: =Premissas!B11*Premissas!B12 -> 7976 | C8: =IF(B19=0,0,B8/B19) -> 0.063209031 | D8: =Premissas!C11*Premissas!C12 -> 34895 | E8: =IF(D19=0,0,D8/D19) -> 0.085589895 | F8: =IF(B8=0,0,(D8-B8)/ABS(B8)) -> 3.375 | G8: =Premissas!D11*Premissas!D12 -> 59820 | H8: =IF(G19=0,0,G8/G19) -> 0.081112304 | I8: =IF(D8=0,0,(G8-D8)/ABS(D8)) -> 0.71428571
A9: Trilha 3 — Burocracia | B9: =Premissas!B13*Premissas!B14 -> 4764 | C9: =IF(B19=0,0,B9/B19) -> 0.037754241 | D9: =Premissas!C13*Premissas!C14 -> 15880 | E9: =IF(D19=0,0,D9/D19) -> 0.038950208 | F9: =IF(B9=0,0,(D9-B9)/ABS(B9)) -> 2.3333333 | G9: =Premissas!D13*Premissas!D14 -> 25805 | H9: =IF(G19=0,0,G9/G19) -> 0.03499002 | I9: =IF(D9=0,0,(G9-D9)/ABS(D9)) -> 0.625
A10: Análise de Deal Avulsa | B10: =Premissas!B15*Premissas!B16 -> 5955 | C10: =IF(B19=0,0,B10/B19) -> 0.047192801 | D10: =Premissas!C15*Premissas!C16 -> 17865 | E10: =IF(D19=0,0,D10/D19) -> 0.043818985 | F10: =IF(B10=0,0,(D10-B10)/ABS(B10)) -> 2 | G10: =Premissas!D15*Premissas!D16 -> 33745 | H10: =IF(G19=0,0,G10/G19) -> 0.04575618 | I10: =IF(D10=0,0,(G10-D10)/ABS(D10)) -> 0.88888889
A11: Mentoria individual | B11: =Premissas!B17*Premissas!B18 -> 14000 | C11: =IF(B19=0,0,B11/B19) -> 0.11094865 | D11: =Premissas!C17*Premissas!C18 -> 42000 | E11: =IF(D19=0,0,D11/D19) -> 0.10301692 | F11: =IF(B11=0,0,(D11-B11)/ABS(B11)) -> 2 | G11: =Premissas!D17*Premissas!D18 -> 63000 | H11: =IF(G19=0,0,G11/G19) -> 0.085424192 | I11: =IF(D11=0,0,(G11-D11)/ABS(D11)) -> 0.5
A12: Inspeções | B12: =Premissas!B19*Premissas!B20 -> 7600 | C12: =IF(B19=0,0,B12/B19) -> 0.060229267 | D12: =Premissas!C19*Premissas!C20 -> 19000 | E12: =IF(D19=0,0,D12/D19) -> 0.046602894 | F12: =IF(B12=0,0,(D12-B12)/ABS(B12)) -> 1.5 | G12: =Premissas!D19*Premissas!D20 -> 30400 | H12: =IF(G19=0,0,G12/G19) -> 0.041220563 | I12: =IF(D12=0,0,(G12-D12)/ABS(D12)) -> 0.6
A13: Due diligence | B13: =Premissas!B21*Premissas!B22 -> 9000 | C13: =IF(B19=0,0,B13/B19) -> 0.071324133 | D13: =Premissas!C21*Premissas!C22 -> 21600 | E13: =IF(D19=0,0,D13/D19) -> 0.052980132 | F13: =IF(B13=0,0,(D13-B13)/ABS(B13)) -> 1.4 | G13: =Premissas!D21*Premissas!D22 -> 36000 | H13: =IF(G19=0,0,G13/G19) -> 0.048813824 | I13: =IF(D13=0,0,(G13-D13)/ABS(D13)) -> 0.66666667
A14: Participação em flips (20% lucro) | B14: =Premissas!B23*Premissas!B24*Premissas!B25 -> 12000 | C14: =IF(B19=0,0,B14/B19) -> 0.095098843 | D14: =Premissas!C23*Premissas!C24*Premissas!C25 -> 30000 | E14: =IF(D19=0,0,D14/D19) -> 0.073583517 | F14: =IF(B14=0,0,(D14-B14)/ABS(B14)) -> 1.5 | G14: =Premissas!D23*Premissas!D24*Premissas!D25 -> 64000 | H14: =IF(G19=0,0,G14/G19) -> 0.086780132 | I14: =IF(D14=0,0,(G14-D14)/ABS(D14)) -> 1.1333333
A15: Marketplace / referrals | B15: =Premissas!B26 -> 3000 | C15: =IF(B19=0,0,B15/B19) -> 0.023774711 | D15: =Premissas!C26 -> 16000 | E15: =IF(D19=0,0,D15/D19) -> 0.039244543 | F15: =IF(B15=0,0,(D15-B15)/ABS(B15)) -> 4.3333333 | G15: =Premissas!D26 -> 38000 | H15: =IF(G19=0,0,G15/G19) -> 0.051525703 | I15: =IF(D15=0,0,(G15-D15)/ABS(D15)) -> 1.375
A16: Radar avulso + patrocínio B2B | B16: =Premissas!B27 -> 1000 | C16: =IF(B19=0,0,B16/B19) -> 0.0079249036 | D16: =Premissas!C27 -> 6000 | E16: =IF(D19=0,0,D16/D19) -> 0.014716703 | F16: =IF(B16=0,0,(D16-B16)/ABS(B16)) -> 5 | G16: =Premissas!D27 -> 18000 | H16: =IF(G19=0,0,G16/G19) -> 0.024406912 | I16: =IF(D16=0,0,(G16-D16)/ABS(D16)) -> 2
A17: Receita Bruta Total | B17: =SUM(B5:B16) -> 140205 | C17: =IF(B19=0,0,B17/B19) -> 1.1111111 | D17: =SUM(D5:D16) -> 453000 | E17: =IF(D19=0,0,D17/D19) -> 1.1111111 | F17: =IF(B17=0,0,(D17-B17)/ABS(B17)) -> 2.2309832 | G17: =SUM(G5:G16) -> 819440 | H17: =IF(G19=0,0,G17/G19) -> 1.1111111 | I17: =IF(D17=0,0,(G17-D17)/ABS(D17)) -> 0.80891832
A18: (–) Deduções / impostos sobre receita | B18: =-B17*Premissas!B43 -> -14020.5 | C18: =IF(B19=0,0,B18/B19) -> -0.11111111 | D18: =-D17*Premissas!C43 -> -45300 | E18: =IF(D19=0,0,D18/D19) -> -0.11111111 | F18: =IF(B18=0,0,(D18-B18)/ABS(B18)) -> -2.2309832 | G18: =-G17*Premissas!D43 -> -81944 | H18: =IF(G19=0,0,G18/G19) -> -0.11111111 | I18: =IF(D18=0,0,(G18-D18)/ABS(D18)) -> -0.80891832
A19: RECEITA LÍQUIDA | B19: =B17+B18 -> 126184.5 | C19: =IF(B19=0,0,B19/B19) -> 1 | D19: =D17+D18 -> 407700 | E19: =IF(D19=0,0,D19/D19) -> 1 | F19: =IF(B19=0,0,(D19-B19)/ABS(B19)) -> 2.2309832 | G19: =G17+G18 -> 737496 | H19: =IF(G19=0,0,G19/G19) -> 1 | I19: =IF(D19=0,0,(G19-D19)/ABS(D19)) -> 0.80891832
A20: CUSTO DOS SERVIÇOS PRESTADOS (CSP)
A21: Taxas de pagamento e plataforma | B21: =-SUM(B5:B10)*Premissas!B29 -> -5616.3 | C21: =IF(B19=0,0,B21/B19) -> -0.044508636 | D21: =-SUM(D5:D10)*Premissas!C29 -> -19104 | E21: =IF(D19=0,0,D21/D19) -> -0.046857984 | F21: =IF(B21=0,0,(D21-B21)/ABS(B21)) -> -2.4015277 | G21: =-SUM(G5:G10)*Premissas!D29 -> -34202.4 | H21: =IF(G19=0,0,G21/G19) -> -0.046376387 | I21: =IF(D21=0,0,(G21-D21)/ABS(D21)) -> -0.79032663
A22: Comissões de afiliados | B22: =-SUM(B5:B10)*Premissas!B30 -> -3744.2 | C22: =IF(B19=0,0,B22/B19) -> -0.029672424 | D22: =-SUM(D5:D10)*Premissas!C30 -> -15920 | E22: =IF(D19=0,0,D22/D19) -> -0.03904832 | F22: =IF(B22=0,0,(D22-B22)/ABS(B22)) -> -3.2519096 | G22: =-SUM(G5:G10)*Premissas!D30 -> -28502 | H22: =IF(G19=0,0,G22/G19) -> -0.038646989 | I22: =IF(D22=0,0,(G22-D22)/ABS(D22)) -> -0.79032663
A23: Repasse a parceiros (serviços/mentoria/flips) | B23: =-(B11+B12+B13+B14)*Premissas!B31 -> -17040 | C23: =IF(B19=0,0,B23/B19) -> -0.13504036 | D23: =-(D11+D12+D13+D14)*Premissas!C31 -> -45040 | E23: =IF(D19=0,0,D23/D19) -> -0.11047339 | F23: =IF(B23=0,0,(D23-B23)/ABS(B23)) -> -1.6431925 | G23: =-(G11+G12+G13+G14)*Premissas!D31 -> -77360 | H23: =IF(G19=0,0,G23/G19) -> -0.10489548 | I23: =IF(D23=0,0,(G23-D23)/ABS(D23)) -> -0.71758437
A24: Custos diretos de inspeção/DD | B24: =-(Premissas!B19*Premissas!B32+Premissas!B21*Premissas!B33) -> -8000 | C24: =IF(B19=0,0,B24/B19) -> -0.063399229 | D24: =-(Premissas!C19*Premissas!C32+Premissas!C21*Premissas!C33) -> -19600 | E24: =IF(D19=0,0,D24/D19) -> -0.048074565 | F24: =IF(B24=0,0,(D24-B24)/ABS(B24)) -> -1.45 | G24: =-(Premissas!D19*Premissas!D32+Premissas!D21*Premissas!D33) -> -32000 | H24: =IF(G19=0,0,G24/G19) -> -0.043390066 | I24: =IF(D24=0,0,(G24-D24)/ABS(D24)) -> -0.63265306
A25: Infraestrutura da plataforma | B25: =-Premissas!B34 -> -4400 | C25: =IF(B19=0,0,B25/B19) -> -0.034869576 | D25: =-Premissas!C34 -> -5800 | E25: =IF(D19=0,0,D25/D19) -> -0.014226147 | F25: =IF(B25=0,0,(D25-B25)/ABS(B25)) -> -0.31818182 | G25: =-Premissas!D34 -> -7500 | H25: =IF(G19=0,0,G25/G19) -> -0.010169547 | I25: =IF(D25=0,0,(G25-D25)/ABS(D25)) -> -0.29310345
A26: Produção de conteúdo/cursos | B26: =-Premissas!B35 -> -6000 | C26: =IF(B19=0,0,B26/B19) -> -0.047549422 | D26: =-Premissas!C35 -> -10000 | E26: =IF(D19=0,0,D26/D19) -> -0.024527839 | F26: =IF(B26=0,0,(D26-B26)/ABS(B26)) -> -0.66666667 | G26: =-Premissas!D35 -> -14000 | H26: =IF(G19=0,0,G26/G19) -> -0.018983154 | I26: =IF(D26=0,0,(G26-D26)/ABS(D26)) -> -0.4
A27: CSP Total | B27: =SUM(B21:B26) -> -44800.5 | C27: =IF(B19=0,0,B27/B19) -> -0.35503964 | D27: =SUM(D21:D26) -> -115464 | E27: =IF(D19=0,0,D27/D19) -> -0.28320824 | F27: =IF(B27=0,0,(D27-B27)/ABS(B27)) -> -1.5772927 | G27: =SUM(G21:G26) -> -193564.4 | H27: =IF(G19=0,0,G27/G19) -> -0.26246163 | I27: =IF(D27=0,0,(G27-D27)/ABS(D27)) -> -0.67640477
A28: LUCRO BRUTO | B28: =B19+B27 -> 81384 | C28: =IF(B19=0,0,B28/B19) -> 0.64496036 | D28: =D19+D27 -> 292236 | E28: =IF(D19=0,0,D28/D19) -> 0.71679176 | F28: =IF(B28=0,0,(D28-B28)/ABS(B28)) -> 2.5908287 | G28: =G19+G27 -> 543931.6 | H28: =IF(G19=0,0,G28/G19) -> 0.73753837 | I28: =IF(D28=0,0,(G28-D28)/ABS(D28)) -> 0.86127513
A29: DESPESAS OPERACIONAIS
A30: Marketing e distribuição | B30: =-Premissas!B37 -> -4000 | C30: =IF(B19=0,0,B30/B19) -> -0.031699614 | D30: =-Premissas!C37 -> -12000 | E30: =IF(D19=0,0,D30/D19) -> -0.029433407 | F30: =IF(B30=0,0,(D30-B30)/ABS(B30)) -> -2 | G30: =-Premissas!D37 -> -22000 | H30: =IF(G19=0,0,G30/G19) -> -0.02983067 | I30: =IF(D30=0,0,(G30-D30)/ABS(D30)) -> -0.83333333
A31: Pró-labore (gestão/tecnologia) | B31: =-Premissas!B38 -> -12000 | C31: =IF(B19=0,0,B31/B19) -> -0.095098843 | D31: =-Premissas!C38 -> -24000 | E31: =IF(D19=0,0,D31/D19) -> -0.058866814 | F31: =IF(B31=0,0,(D31-B31)/ABS(B31)) -> -1 | G31: =-Premissas!D38 -> -36000 | H31: =IF(G19=0,0,G31/G19) -> -0.048813824 | I31: =IF(D31=0,0,(G31-D31)/ABS(D31)) -> -0.5 | K31: e parceria?
A32: Contabilidade, jurídico e compliance | B32: =-Premissas!B39 -> -3000 | C32: =IF(B19=0,0,B32/B19) -> -0.023774711 | D32: =-Premissas!C39 -> -7000 | E32: =IF(D19=0,0,D32/D19) -> -0.017169487 | F32: =IF(B32=0,0,(D32-B32)/ABS(B32)) -> -1.3333333 | G32: =-Premissas!D39 -> -9000 | H32: =IF(G19=0,0,G32/G19) -> -0.012203456 | I32: =IF(D32=0,0,(G32-D32)/ABS(D32)) -> -0.28571429 | K32: inspecoes?
A33: Software e administrativas | B33: =-Premissas!B40 -> -2000 | C33: =IF(B19=0,0,B33/B19) -> -0.015849807 | D33: =-Premissas!C40 -> -3000 | E33: =IF(D19=0,0,D33/D19) -> -0.0073583517 | F33: =IF(B33=0,0,(D33-B33)/ABS(B33)) -> -0.5 | G33: =-Premissas!D40 -> -4000 | H33: =IF(G19=0,0,G33/G19) -> -0.0054237582 | I33: =IF(D33=0,0,(G33-D33)/ABS(D33)) -> -0.33333333
A34: Pessoal — analista/VA | B34: =-Premissas!B41 -> 0 | C34: =IF(B19=0,0,B34/B19) -> 0 | D34: =-Premissas!C41 -> -8000 | E34: =IF(D19=0,0,D34/D19) -> -0.019622271 | F34: =IF(B34=0,0,(D34-B34)/ABS(B34)) -> 0 | G34: =-Premissas!D41 -> -18000 | H34: =IF(G19=0,0,G34/G19) -> -0.024406912 | I34: =IF(D34=0,0,(G34-D34)/ABS(D34)) -> -1.25
A35: Despesas Operacionais Total | B35: =SUM(B30:B34) -> -21000 | C35: =IF(B19=0,0,B35/B19) -> -0.16642298 | D35: =SUM(D30:D34) -> -54000 | E35: =IF(D19=0,0,D35/D19) -> -0.13245033 | F35: =IF(B35=0,0,(D35-B35)/ABS(B35)) -> -1.5714286 | G35: =SUM(G30:G34) -> -89000 | H35: =IF(G19=0,0,G35/G19) -> -0.12067862 | I35: =IF(D35=0,0,(G35-D35)/ABS(D35)) -> -0.64814815
A36: EBITDA | B36: =B28+B35 -> 60384 | C36: =IF(B19=0,0,B36/B19) -> 0.47853738 | D36: =D28+D35 -> 238236 | E36: =IF(D19=0,0,D36/D19) -> 0.58434143 | F36: =IF(B36=0,0,(D36-B36)/ABS(B36)) -> 2.9453498 | G36: =G28+G35 -> 454931.6 | H36: =IF(G19=0,0,G36/G19) -> 0.61685975 | I36: =IF(D36=0,0,(G36-D36)/ABS(D36)) -> 0.90958377
A37: (–) Depreciação e amortização | B37: =-Premissas!B45/3 -> -1000 | C37: =IF(B19=0,0,B37/B19) -> -0.0079249036 | D37: =-(Premissas!B45+Premissas!C45)/3 -> -1500 | E37: =IF(D19=0,0,D37/D19) -> -0.0036791759 | F37: =IF(B37=0,0,(D37-B37)/ABS(B37)) -> -0.5 | G37: =-(Premissas!B45+Premissas!C45+Premissas!D45)/3 -> -2000 | H37: =IF(G19=0,0,G37/G19) -> -0.0027118791 | I37: =IF(D37=0,0,(G37-D37)/ABS(D37)) -> -0.33333333
A38: EBIT (Resultado Operacional) | B38: =B36+B37 -> 59384 | C38: =IF(B19=0,0,B38/B19) -> 0.47061248 | D38: =D36+D37 -> 236736 | E38: =IF(D19=0,0,D38/D19) -> 0.58066225 | F38: =IF(B38=0,0,(D38-B38)/ABS(B38)) -> 2.9865284 | G38: =G36+G37 -> 452931.6 | H38: =IF(G19=0,0,G38/G19) -> 0.61414787 | I38: =IF(D38=0,0,(G38-D38)/ABS(D38)) -> 0.913235
A39: Resultado financeiro | B39: =0 -> 0 | C39: =IF(B19=0,0,B39/B19) -> 0 | D39: =0 -> 0 | E39: =IF(D19=0,0,D39/D19) -> 0 | F39: =IF(B39=0,0,(D39-B39)/ABS(B39)) -> 0 | G39: =0 -> 0 | H39: =IF(G19=0,0,G39/G19) -> 0 | I39: =IF(D39=0,0,(G39-D39)/ABS(D39)) -> 0
A40: LAIR (Lucro antes de IR) | B40: =B38+B39 -> 59384 | C40: =IF(B19=0,0,B40/B19) -> 0.47061248 | D40: =D38+D39 -> 236736 | E40: =IF(D19=0,0,D40/D19) -> 0.58066225 | F40: =IF(B40=0,0,(D40-B40)/ABS(B40)) -> 2.9865284 | G40: =G38+G39 -> 452931.6 | H40: =IF(G19=0,0,G40/G19) -> 0.61414787 | I40: =IF(D40=0,0,(G40-D40)/ABS(D40)) -> 0.913235
A41: (–) IR/CSLL | B41: =-MAX(0,B40)*Premissas!B44 -> -8907.6 | C41: =IF(B19=0,0,B41/B19) -> -0.070591871 | D41: =-MAX(0,D40)*Premissas!C44 -> -35510.4 | E41: =IF(D19=0,0,D41/D19) -> -0.087099338 | F41: =IF(B41=0,0,(D41-B41)/ABS(B41)) -> -2.9865284 | G41: =-MAX(0,G40)*Premissas!D44 -> -67939.74 | H41: =IF(G19=0,0,G41/G19) -> -0.092122181 | I41: =IF(D41=0,0,(G41-D41)/ABS(D41)) -> -0.913235
...

Sheet Divisão de Lucros
A1: RealRisk — Divisão de Lucros por Fonte de Receita
A2: Separa o que a plataforma ORIGINA (split alto) do que é deal PRÓPRIO do Jales (só override). Estevan/Samuel = custo, não sócios.
B4: Ano 1 | C4: Ano 2 | D4: Ano 3 | E4: 3 anos (acum.)
A5: Lucro Líquido da empresa (da DRE) | B5: =DRE!B42 -> 50476.4 | C5: =DRE!D42 -> 201225.6 | D5: =DRE!G42 -> 384991.86 | E5: =SUM(B5:D5) -> 636693.86
A6: % payout (lucro distribuído) | B6: 0.5 | C6: 0.7 | D6: 0.6 | G6: reduza p/ reter caixa
A7: Lucro distribuível da empresa | B7: =B5*B6 -> 25238.2 | C7: =C5*C6 -> 140857.92 | D7: =D5*D6 -> 230995.12 | E7: =SUM(B7:D7) -> 397091.24
A9: RECEITA POR FONTE (dentro da empresa)
A10: Plataforma (assinaturas, cursos, parcerias) | B10: =DRE!B5+DRE!B6+DRE!B7+DRE!B8+DRE!B9+DRE!B15+DRE!B16 -> 91650 | C10: =DRE!D5+DRE!D6+DRE!D7+DRE!D8+DRE!D9+DRE!D15+DRE!D16 -> 322535 | D10: =DRE!G5+DRE!G6+DRE!G7+DRE!G8+DRE!G9+DRE!G15+DRE!G16 -> 592295 | E10: =SUM(B10:D10) -> 1006480
A11: Serviços de deal (inspeção, DD, mentoria, avulsa) | B11: =DRE!B10+DRE!B11+DRE!B12+DRE!B13 -> 36555 | C11: =DRE!D10+DRE!D11+DRE!D12+DRE!D13 -> 100465 | D11: =DRE!G10+DRE!G11+DRE!G12+DRE!G13 -> 163145 | E11: =SUM(B11:D11) -> 300165
A12: Flips ORIGINADOS pela plataforma | B12: =DRE!B14 -> 12000 | C12: =DRE!D14 -> 30000 | D12: =DRE!G14 -> 64000 | E12: =SUM(B12:D12) -> 106000
A13: Receita Bruta Total (conferência) | B13: =B10+B11+B12 -> 140205 | C13: =C10+C11+C12 -> 453000 | D13: =D10+D11+D12 -> 819440 | E13: =SUM(B13:D13) -> 1412645
A15: LUCRO ATRIBUÍDO POR FONTE | G15: (= distribuível x receita fonte / total)
A16: Lucro — Plataforma | B16: =IF(B13=0,0,B7*B10/B13) -> 16497.85 | C16: =IF(C13=0,0,C7*C10/C13) -> 100290.53 | D16: =IF(D13=0,0,D7*D10/D13) -> 166964.33 | E16: =SUM(B16:D16) -> 283752.71
A17: Lucro — Serviços de deal | B17: =IF(B13=0,0,B7*B11/B13) -> 6580.2389 | C17: =IF(C13=0,0,C7*C11/C13) -> 31239.053 | D17: =IF(D13=0,0,D7*D11/D13) -> 45989.576 | E17: =SUM(B17:D17) -> 83808.868
A18: Lucro — Flips originados pela plataforma | B18: =IF(B13=0,0,B7*B12/B13) -> 2160.1113 | C18: =IF(C13=0,0,C7*C12/C13) -> 9328.3391 | D18: =IF(D13=0,0,D7*D12/D13) -> 18041.208 | E18: =SUM(B18:D18) -> 29529.658
A20: SPLIT — PLATAFORMA | F20: %
A21: Lucas | B21: =B16*$F21 -> 9898.7099 | C21: =C16*$F21 -> 60174.317 | D21: =D16*$F21 -> 100178.6 | E21: =SUM(B21:D21) -> 170251.63 | F21: 0.6
A22: Jales Castro | B22: =B16*$F22 -> 6599.1399 | C22: =C16*$F22 -> 40116.211 | D22: =D16*$F22 -> 66785.733 | E22: =SUM(B22:D22) -> 113501.08 | F22: 0.4
A23: soma % | F23: =SUM(F21:F22) -> 1 | G23: =IF(ABS(F23-1)<0.0001,"100% OK","AJUSTAR %") -> 100% OK
A25: SPLIT — SERVIÇOS DE DEAL | F25: % | G25: sugestão 45/55 — execução/licença do Jales
A26: Lucas | B26: =B17*$F26 -> 2632.0956 | C26: =C17*$F26 -> 12495.621 | D26: =D17*$F26 -> 18395.83 | E26: =SUM(B26:D26) -> 33523.547 | F26: 0.4
A27: Jales Castro | B27: =B17*$F27 -> 3948.1434 | C27: =C17*$F27 -> 18743.432 | D27: =D17*$F27 -> 27593.746 | E27: =SUM(B27:D27) -> 50285.321 | F27: 0.6
A28: soma % | F28: =SUM(F26:F27) -> 1 | G28: =IF(ABS(F28-1)<0.0001,"100% OK","AJUSTAR %") -> 100% OK
A30: SPLIT — FLIPS ORIGINADOS PELA PLATAFORMA | F30: % | G30: sugestão 50/50 — sem a plataforma não existiria
A31: Lucas | B31: =B18*$F31 -> 1080.0556 | C31: =C18*$F31 -> 4664.1695 | D31: =D18*$F31 -> 9020.604 | E31: =SUM(B31:D31) -> 14764.829 | F31: 0.5
A32: Jales Castro | B32: =B18*$F32 -> 1080.0556 | C32: =C18*$F32 -> 4664.1695 | D32: =D18*$F32 -> 9020.604 | E32: =SUM(B32:D32) -> 14764.829 | F32: 0.5
A33: soma % | F33: =SUM(F31:F32) -> 1 | G33: =IF(ABS(F33-1)<0.0001,"100% OK","AJUSTAR %") -> 100% OK
A35: OVERRIDE — DEALS PRÓPRIOS DO JALES (fora da DRE) | G35: deals grandes que ele já faz; plataforma só estrutura/escala
A36: Nº de deals próprios estruturados pela plataforma | B36: 0 | C36: 1 | D36: 2 | G36: ex.: fazenda desmembrada em 30+ lotes
A37: Lucro médio por deal próprio (US$) | B37: 300000 | C37: 300000 | D37: 320000 | G37: deal grande — ajustar à realidade
A38: % override da plataforma sobre o deal | B38: 0.1 | C38: 0.1 | D38: 0.1 | G38: fee por estruturar/levar capital/comprador
A39: Override total recebido pela plataforma | B39: =B36*B37*B38 -> 0 | C39: =C36*C37*C38 -> 30000 | D39: =D36*D37*D38 -> 64000 | E39: =SUM(B39:D39) -> 94000
A40: Split do override | F40: %
A41: Lucas | B41: =B39*$F41 -> 0 | C41: =C39*$F41 -> 18000 | D41: =D39*$F41 -> 38400 | E41: =SUM(B41:D41) -> 56400 | F41: 0.6
A42: Jales Castro | B42: =B39*$F42 -> 0 | C42: =C39*$F42 -> 12000 | D42: =D39*$F42 -> 25600 | E42: =SUM(B42:D42) -> 37600 | F42: 0.4
A43: soma % | F43: =SUM(F41:F42) -> 1 | G43: override-heavy p/ Lucas: é o fee da plataforma
A44: Jales retém do próprio deal (1 − override) | B44: =B36*B37*(1-B38) -> 0 | C44: =C36*C37*(1-C38) -> 270000 | D44: =D36*D37*(1-D38) -> 576000 | E44: =SUM(B44:D44) -> 846000
A46: RESULTADO TOTAL POR SÓCIO
A47: Lucas — total (empresa + override) | B47: =B21+B26+B31+B41 -> 13610.861 | C47: =C21+C26+C31+C41 -> 95334.108 | D47: =D21+D26+D31+D41 -> 165995.03 | E47: =SUM(B47:D47) -> 274940
A48: Jales — da empresa + override | B48: =B22+B27+B32+B42 -> 11627.339 | C48: =C22+C27+C32+C42 -> 75523.812 | D48: =D22+D27+D32+D42 -> 129000.08 | E48: =SUM(B48:D48) -> 216151.23
...

Sheet Balanço
A1: Balanço Patrimonial Simplificado (fim de cada ano, US$)
A2: Simplificação para fins de indicadores — caixa derivado da identidade contábil
B4: Ano 1 | C4: Ano 2 | D4: Ano 3
A5: PASSIVO + PL (calculado primeiro)
A6: Receita diferida (assinaturas antecipadas) | B6: =DRE!B5*Premissas!B47 -> 16800 | C6: =DRE!D5*Premissas!C47 -> 63000 | D6: =DRE!G5*Premissas!D47 -> 121800
A7: Contas a pagar (fornecedores/repasses) | B7: =-(DRE!B27+DRE!B35)*Premissas!B49 -> 2632.02 | C7: =-(DRE!D27+DRE!D35)*Premissas!C49 -> 6778.56 | D7: =-(DRE!G27+DRE!G35)*Premissas!D49 -> 11302.576
A8: Passivo Circulante Total | B8: =B6+B7 -> 19432.02 | C8: =C6+C7 -> 69778.56 | D8: =D6+D7 -> 133102.58
A9: Passivo Não Circulante | B9: =0 -> 0 | C9: =0 -> 0 | D9: =0 -> 0
A10: Capital social aportado | B10: =Premissas!B46 -> 12000 | C10: =Premissas!C46 -> 12000 | D10: =Premissas!D46 -> 12000
A11: Lucros acumulados | B11: =DRE!B42 -> 50476.4 | C11: =B11+DRE!D42 -> 251702 | D11: =C11+DRE!G42 -> 636693.86
A12: Patrimônio Líquido Total | B12: =B10+B11 -> 62476.4 | C12: =C10+C11 -> 263702 | D12: =D10+D11 -> 648693.86
A13: PASSIVO TOTAL + PL | B13: =B8+B9+B12 -> 81908.42 | C13: =C8+C9+C12 -> 333480.56 | D13: =D8+D9+D12 -> 781796.44
A15: ATIVO
A16: Contas a receber | B16: =DRE!B17*Premissas!B48 -> 7010.25 | C16: =DRE!D17*Premissas!C48 -> 22650 | D16: =DRE!G17*Premissas!D48 -> 40972
A17: Imobilizado líquido | B17: =Premissas!B45+DRE!B37 -> 2000 | C17: =B17+Premissas!C45+DRE!D37 -> 2000 | D17: =C17+Premissas!D45+DRE!G37 -> 1500
A18: Caixa e equivalentes (plug contábil) | B18: =B13-B16-B17 -> 72898.17 | C18: =C13-C16-C17 -> 308830.56 | D18: =D13-D16-D17 -> 739324.44
A19: Ativo Circulante (Caixa + AR) | B19: =B18+B16 -> 79908.42 | C19: =C18+C16 -> 331480.56 | D19: =D18+D16 -> 780296.44
A20: ATIVO TOTAL | B20: =B19+B17 -> 81908.42 | C20: =C19+C17 -> 333480.56 | D20: =D19+D17 -> 781796.44
A21: Check (Ativo − Passivo+PL = 0) | B21: =B20-B13 -> 0 | C21: =C20-C13 -> 0 | D21: =D20-D13 -> 0

Sheet Indicadores
A1: Painel de Indicadores — RealRisk (3 anos)
A3: Indicador | B3: Ano 1 | C3: Ano 2 | D3: Ano 3 | E3: Leitura
A4: RENTABILIDADE (DRE)
A5: Margem Bruta — eficiência produtiva | B5: =DRE!B28/DRE!B19 -> 0.64496036 | C5: =DRE!D28/DRE!D19 -> 0.71679176 | D5: =DRE!G28/DRE!G19 -> 0.73753837 | E5: Lucro bruto / receita líquida. Quanto sobra após custos diretos de entrega
A6: CSP % da receita líquida | B6: =-DRE!B27/DRE!B19 -> 0.35503964 | C6: =-DRE!D27/DRE!D19 -> 0.28320824 | D6: =-DRE!G27/DRE!G19 -> 0.26246163 | E6: Peso dos custos diretos (taxas, repasses, infra, produção)
A7: Margem EBITDA — potencial de geração de caixa | B7: =DRE!B36/DRE!B19 -> 0.47853738 | C7: =DRE!D36/DRE!D19 -> 0.58434143 | D7: =DRE!G36/DRE!G19 -> 0.61685975 | E7: Resultado antes de juros, impostos, D&A
A8: Margem Operacional (EBIT) — desempenho das operações | B8: =DRE!B38/DRE!B19 -> 0.47061248 | C8: =DRE!D38/DRE!D19 -> 0.58066225 | D8: =DRE!G38/DRE!G19 -> 0.61414787 | E8: Resultado operacional / receita líquida
A9: Margem Líquida — lucratividade final | B9: =DRE!B42/DRE!B19 -> 0.4000206 | C9: =DRE!D42/DRE!D19 -> 0.49356291 | D9: =DRE!G42/DRE!G19 -> 0.52202569 | E9: O que sobra para o sócio de cada $1 de receita
A10: Lucratividade (LL / Receita Bruta) | B10: =DRE!B42/DRE!B17 -> 0.36001854 | C10: =DRE!D42/DRE!D17 -> 0.44420662 | D10: =DRE!G42/DRE!G17 -> 0.46982312 | E10: Visão sobre o faturamento total
A11: RETORNO
A12: ROI — retorno sobre investimento | B12: =DRE!B42/(Premissas!B46+Premissas!B45) -> 3.3650933 | C12: =DRE!D42/(Premissas!C46+Premissas!B45+Premissas!C45) -> 12.195491 | D12: =DRE!G42/(Premissas!D46+Premissas!B45+Premissas!C45+Premissas!D45) -> 21.388437 | E12: LL / (capital aportado + capex acumulado)
A13: ROE — retorno sobre PL | B13: =DRE!B42/Balanço!B12 -> 0.80792747 | C13: =DRE!D42/Balanço!C12 -> 0.76307954 | D13: =DRE!G42/Balanço!D12 -> 0.59348775 | E13: LL / patrimônio líquido de fim de ano
A14: Giro do Ativo | B14: =DRE!B19/Balanço!B20 -> 1.5405559 | C14: =DRE!D19/Balanço!C20 -> 1.22256 | D14: =DRE!G19/Balanço!D20 -> 0.94333508 | E14: Receita líquida / ativo total — quanto o ativo "roda" por ano
A15: ROA (LL / Ativo total) | B15: =DRE!B42/Balanço!B20 -> 0.6162541 | C15: =DRE!D42/Balanço!C20 -> 0.60341029 | D15: =DRE!G42/Balanço!D20 -> 0.49244515 | E15: Eficiência do ativo em gerar lucro
A16: LIQUIDEZ (Balanço)
A17: Liquidez Imediata (Caixa / PC) | B17: =Balanço!B18/Balanço!B8 -> 3.7514458 | C17: =Balanço!C18/Balanço!C8 -> 4.4258661 | D17: =Balanço!D18/Balanço!D8 -> 5.5545464 | E17: Capacidade de pagar o circulante só com caixa
A18: Liquidez Corrente (AC / PC) | B18: =Balanço!B19/Balanço!B8 -> 4.1122035 | C18: =Balanço!C19/Balanço!C8 -> 4.7504643 | D18: =Balanço!D19/Balanço!D8 -> 5.8623692 | E18: "Liquidez recorrente" — circulante sobre circulante
A19: Liquidez Seca ((AC − Estoques) / PC) | B19: =Balanço!B19/Balanço!B8 -> 4.1122035 | C19: =Balanço!C19/Balanço!C8 -> 4.7504643 | D19: =Balanço!D19/Balanço!D8 -> 5.8623692 | E19: Negócio sem estoque → igual à corrente
A20: Liquidez Geral ((AC+RLP) / (PC+PNC)) | B20: =Balanço!B19/(Balanço!B8+Balanço!B9) -> 4.1122035 | C20: =Balanço!C19/(Balanço!C8+Balanço!C9) -> 4.7504643 | D20: =Balanço!D19/(Balanço!D8+Balanço!D9) -> 5.8623692 | E20: Solvência total — sem dívida de LP, ≈ corrente
A21: ESTRUTURA DE CAPITAL
A22: Endividamento Geral (Passivo / Ativo) | B22: =(Balanço!B8+Balanço!B9)/Balanço!B20 -> 0.23724081 | C22: =(Balanço!C8+Balanço!C9)/Balanço!C20 -> 0.20924326 | D22: =(Balanço!D8+Balanço!D9)/Balanço!D20 -> 0.17025222 | E22: Quanto do ativo é financiado por terceiros (aqui: receita diferida)
A23: Capital de Terceiros / PL | B23: =(Balanço!B8+Balanço!B9)/Balanço!B12 -> 0.31102976 | C23: =(Balanço!C8+Balanço!C9)/Balanço!C12 -> 0.26461142 | D23: =(Balanço!D8+Balanço!D9)/Balanço!D12 -> 0.2051855 | E23: Alavancagem — passivo sobre capital próprio
A24: Imobilização do PL (Imob / PL) | B24: =Balanço!B17/Balanço!B12 -> 0.032012088 | C24: =Balanço!C17/Balanço!C12 -> 0.0075843187 | D24: =Balanço!D17/Balanço!D12 -> 0.0023123388 | E24: Quanto do capital próprio está preso em ativo fixo
A25: UNIT ECONOMICS (Cursos v2 §6)
A26: ARPU expandido (Receita bruta / assinante médio / mês) | B26: =DRE!B17/Premissas!B5/12 -> 292.09375 | C26: =DRE!D17/Premissas!C5/12 -> 251.66667 | D26: =DRE!G17/Premissas!D5/12 -> 235.47126 | E26: Meta cursos v2: > $150/mês
A27: Receita não-assinatura (% da receita bruta) | B27: =1-DRE!B5/DRE!B17 -> 0.65764416 | C27: =1-DRE!D5/DRE!D17 -> 0.60264901 | D27: =1-DRE!G5/DRE!G17 -> 0.57531973 | E27: Diversificação — quanto vem de cursos, serviços e parcerias
